<?xml version="1.0"?>
<robot xmlns:xacro="http://ros.org/wiki/xacro">

<xacro:macro name="cylinder_inertia" params="m r h">
  <inertia  ixx="${m*(3*r*r+h*h)/12}" ixy = "0" ixz = "0"
    iyy="${m*(3*r*r+h*h)/12}" iyz = "0"
    izz="${m*r*r/2}"
  />
</xacro:macro>

<xacro:macro name="box_inertia" params="m x y z">
  <inertia  ixx="${m*(y*y+z*z)/12}" ixy = "0" ixz = "0"
    iyy="${m*(x*x+z*z)/12}" iyz = "0"
    izz="${m*(x*x+z*z)/12}"
  />
</xacro:macro>

<xacro:macro name="sphere_inertia" params="m r">
  <inertia  ixx="${2*m*r*r/5}" ixy = "0" ixz = "0"
    iyy="${2*m*r*r/5}" iyz = "0"
    izz="${2*m*r*r/5}"
  />
</xacro:macro>
<xacro:macro name="wheel" params="lr num jr fr">

<link name="h_${lr}_wheel_${num}">
  <collision>
    <origin xyz="0 0 0" rpy="0 0 0" />
    <geometry>
	<cylinder radius="${wheelRadius}" length="${wheelWidth}"/>
    </geometry>
  </collision>

  <visual>
    <origin xyz="0 0 0" rpy="0 0 0" />
    <geometry>
	<mesh filename="package://car_design_full/meshes/h_${lr}_wheel_${num}.STL" />
    </geometry>
    <material name="material_wheel"/>
  </visual>

  <inertial>
    <origin xyz="0 0 0" rpy="0 0 0" />
    <mass value="${wheelMass}"/>
    <cylinder_inertia m="${wheelMass}" r="${wheelRadius}" h="${wheelWidth}"/>
  </inertial>
</link>

<gazebo reference="h_${lr}_wheel_${num}">
  <mu1 value="1.0"/>
 <mu2 value="1.0"/>
 <kp value="10000000.0" />
 <kd value="1.0" />
 <fdir1 value="0 0 1"/>
  <material>Gazebo/Black</material>
</gazebo>


<joint name="joint_wheel_${lr}_${num}" type="continuous">
  <parent link="base_link"/>
  <child link="h_${lr}_wheel_${num}"/>
  <origin xyz="${jr}"  rpy="${fr}"/>
  <limit effort="1000000000000000000000.0" velocity="10000000000.0"/>
  <axis xyz="0 0 1" rpy="0 0 2" />
</joint>


<transmission name="${lr}_trans_${num}">
  <type>transmission_interface/SimpleTransmission</type>
  <joint name="joint_wheel_${lr}_${num}">
 <hardwareInterface>VelocityJointInterface</hardwareInterface>
 </joint>
  <actuator name="${lr}Motor${num}">
    <hardwareInterface>VelocityJointInterface</hardwareInterface>
    <mechanicalReduction>1</mechanicalReduction>
  </actuator>
</transmission>

</xacro:macro>
</robot>
